Workbook
Name AWCurrentRel: 'Automated View'!$P$2
Name AWLookup: Table3[]
Name AWRelease: 'Automated View'!$A$1
Name AWReleaseEntered: 'Automated View'!$A$1
Name AWReleaseNum: 'Automated View'!$M$2
Name MinVerInfo: Table1[]
Name TcBaseVer: 'Automated View'!$O$2
Name TcLookup: Table2[]
Name TcRelease: 'Automated View'!$A$2
Name TcReleaseNum: 'Automated View'!$N$2

Sheet Automated View
A1: 2606 | B1: <-- Select your Active Workspace version here | E1: =CONCATENATE(COUNTIF(L4:L8460,"Available")," of ",(COUNTIF(L4:L8460,"Available")+COUNTIF(L4:L8460,"Not Supported"))," features supported") -> 2665 of 2665 features supported | M1: AW Version | N1: TC Version | O1: TC Base | P1: AW Future
A2: 2606 | B2: <-- Select your Teamcenter version here | M2: =VLOOKUP(AWRelease,AWLookup,2,FALSE) -> 2606 | N2: =VLOOKUP(TcRelease,TcLookup,3,FALSE) -> 2606 | O2: =IFERROR(VLOOKUP(TcRelease,Table2[#All],2,FALSE),0) -> 2606 | P2: 2612
A3: Active Workspace Release | B3: Category | C3: Area | D3: Topic | E3: Feature | F3: Teamcenter Prior Release Minimum | G3: Teamcenter Current Release Minimum | H3: Minimum Version on Teamcenter 11 | I3: Minimum Version on Teamcenter 12 | J3: Minimum Version on Teamcenter 13 | K3: Minimum Version on Teamcenter 14 | L3: Feature Availability | M3: AW Version Okay | N3: TC Version In Range | O3: TC Version Okay | P3: TC Ver 2 Check | Q3: Combo Okay | R3: Future | S3: Link to What's New Material | T3: Link String for What's New Material | U3: URL to What's New Material
A4: =IF(OR('Raw Data'!A2=0,'Raw Data'!A2="Delete"),"",'Raw Data'!A2) -> 2 | B4: =IF(OR('Raw Data'!B2=0,'Raw Data'!B2="Delete"),"",'Raw Data'!B2) -> Foundation | C4: =IF(OR('Raw Data'!C2=0,'Raw Data'!C2="Delete"),"",'Raw Data'!C2) -> Connectivity | D4: =IF(OR('Raw Data'!D2=0,'Raw Data'!D2="Delete"),"",'Raw Data'!D2) -> Active Integration | E4: =IF(OR('Raw Data'!E2=0,'Raw Data'!E2="Delete"),"",'Raw Data'!E2) -> Open basic documents and models in appropriate application | F4: {=_xlfn.SWITCH(ROUND(VLOOKUP(A4,Table1[#All],3),0),11,H4,12,I4,13,J4,14,K4,"N/A")} -> 13 | G4: {=_xlfn.SWITCH(ROUND(VLOOKUP(A4,Table1[#All],5),0),11,H4,12,I4,13,J4,14,K4,"N/A")} -> 14 | H4: =IF(OR('Raw Data'!H2=0,'Raw Data'!H2="Delete"),"",'Raw Data'!H2) -> 13 | I4: =IF(OR('Raw Data'!I2=0,'Raw Data'!I2="Delete"),"",'Raw Data'!I2) -> 14 | J4: =IF(OR('Raw Data'!J2=0,'Raw Data'!J2="Delete"),"",'Raw Data'!J2) | K4: =IF(OR('Raw Data'!K2=0,'Raw Data'!K2="Delete"),"",'Raw Data'!K2) | L4: =R4 -> Available | M4: =IF(A4="","",IF(OR(AWReleaseNum>=A4,AWReleaseNum=0),"Available","Not Supported")) -> Available | N4: =IF(A4="","",IF(TcRelease="Any","Available",IF(OR(AND(TcReleaseNum>=VLOOKUP(AWReleaseNum,MinVerInfo,3,FALSE),TcReleaseNum<=VLOOKUP(AWReleaseNum,MinVerInfo,4,FALSE)),AND(TcReleaseNum>=VLOOKUP(AWReleaseNum,MinVerInfo,5,FALSE),TcReleaseNum<=VLOOKUP(AWReleaseNum,MinVerInfo,6,FALSE))),"Available","Not Supported"))) -> Available | O4: =IF(TcReleaseNum<P4,"Not Supported","Available") -> Available | P4: {=_xlfn.SWITCH(TcBaseVer, 14, K4, 13, J4, 12, I4, 11, IFERROR(VLOOKUP(H4,Table2[#All],3,FALSE),"N/A"),0)} -> 0 | Q4: =IF(TcBaseVer=0,M4,IF(AND(N4="Available",M4="Available",O4="Available"),"Available",IF(M4="","","Not Supported"))) -> Available | R4: =IF(A4>=AWCurrentRel, "Future",Q4) -> Available | S4: =HYPERLINK(U4,T4) -> Not Available | T4: =IFERROR(VLOOKUP(CONCATENATE($B4,"_",$A4),Table4[#All],5,FALSE),"Not Available") -> Not Available | U4: =IFERROR(VLOOKUP(CONCATENATE(B4,"_",A4),Table4[#All],6,FALSE),"")
A5: =IF(OR('Raw Data'!A3=0,'Raw Data'!A3="Delete"),"",'Raw Data'!A3) -> 2 | B5: =IF(OR('Raw Data'!B3=0,'Raw Data'!B3="Delete"),"",'Raw Data'!B3) -> Foundation | C5: =IF(OR('Raw Data'!C3=0,'Raw Data'!C3="Delete"),"",'Raw Data'!C3) -> Connectivity | D5: =IF(OR('Raw Data'!D3=0,'Raw Data'!D3="Delete"),"",'Raw Data'!D3) -> Active Integration | E5: =IF(OR('Raw Data'!E3=0,'Raw Data'!E3="Delete"),"",'Raw Data'!E3) -> Open TcVis on simple configured structure | F5: {=_xlfn.SWITCH(ROUND(VLOOKUP(A5,Table1[#All],3),0),11,H5,12,I5,13,J5,14,K5,"N/A")} -> 13 | G5: {=_xlfn.SWITCH(ROUND(VLOOKUP(A5,Table1[#All],5),0),11,H5,12,I5,13,J5,14,K5,"N/A")} -> 14 | H5: =IF(OR('Raw Data'!H3=0,'Raw Data'!H3="Delete"),"",'Raw Data'!H3) -> 13 | I5: =IF(OR('Raw Data'!I3=0,'Raw Data'!I3="Delete"),"",'Raw Data'!I3) -> 14 | J5: =IF(OR('Raw Data'!J3=0,'Raw Data'!J3="Delete"),"",'Raw Data'!J3) | K5: =IF(OR('Raw Data'!K3=0,'Raw Data'!K3="Delete"),"",'Raw Data'!K3) | L5: =R5 -> Available | M5: =IF(A5="","",IF(OR(AWReleaseNum>=A5,AWReleaseNum=0),"Available","Not Supported")) -> Available | N5: =IF(A5="","",IF(TcRelease="Any","Available",IF(OR(AND(TcReleaseNum>=VLOOKUP(AWReleaseNum,MinVerInfo,3,FALSE),TcReleaseNum<=VLOOKUP(AWReleaseNum,MinVerInfo,4,FALSE)),AND(TcReleaseNum>=VLOOKUP(AWReleaseNum,MinVerInfo,5,FALSE),TcReleaseNum<=VLOOKUP(AWReleaseNum,MinVerInfo,6,FALSE))),"Available","Not Supported"))) -> Available | O5: =IF(TcReleaseNum<P5,"Not Supported","Available") -> Available | P5: {=_xlfn.SWITCH(TcBaseVer, 14, K5, 13, J5, 12, I5, 11, IFERROR(VLOOKUP(H5,Table2[#All],3,FALSE),"N/A"),0)} -> 0 | Q5: =IF(TcBaseVer=0,M5,IF(AND(N5="Available",M5="Available",O5="Available"),"Available",IF(M5="","","Not Supported"))) -> Available | R5: =IF(A5>=AWCurrentRel, "Future",Q5) -> Available | S5: =HYPERLINK(U5,T5) -> Not Available | T5: =IFERROR(VLOOKUP(CONCATENATE($B5,"_",$A5),Table4[#All],5,FALSE),"Not Available") -> Not Available | U5: =IFERROR(VLOOKUP(CONCATENATE(B5,"_",A5),Table4[#All],6,FALSE),"")
A6: =IF(OR('Raw Data'!A28=0,'Raw Data'!A28="Delete"),"",'Raw Data'!A28) -> 2 | B6: =IF(OR('Raw Data'!B28=0,'Raw Data'!B28="Delete"),"",'Raw Data'!B28) -> Foundation | C6: =IF(OR('Raw Data'!C28=0,'Raw Data'!C28="Delete"),"",'Raw Data'!C28) -> Usability | D6: =IF(OR('Raw Data'!D28=0,'Raw Data'!D28="Delete"),"",'Raw Data'!D28) -> Platform - Active Workspace Framework - Usability | E6: =IF(OR('Raw Data'!E28=0,'Raw Data'!E28="Delete"),"",'Raw Data'!E28) -> Configurable Home Page | F6: {=_xlfn.SWITCH(ROUND(VLOOKUP(A6,Table1[#All],3),0),11,H6,12,I6,13,J6,14,K6,"N/A")} -> 13 | G6: {=_xlfn.SWITCH(ROUND(VLOOKUP(A6,Table1[#All],5),0),11,H6,12,I6,13,J6,14,K6,"N/A")} -> 14 | H6: =IF(OR('Raw Data'!H28=0,'Raw Data'!H28="Delete"),"",'Raw Data'!H28) -> 13 | I6: =IF(OR('Raw Data'!I28=0,'Raw Data'!I28="Delete"),"",'Raw Data'!I28) -> 14 | J6: =IF(OR('Raw Data'!J28=0,'Raw Data'!J28="Delete"),"",'Raw Data'!J28) | K6: =IF(OR('Raw Data'!K28=0,'Raw Data'!K28="Delete"),"",'Raw Data'!K28) | L6: =R6 -> Available | M6: =IF(A6="","",IF(OR(AWReleaseNum>=A6,AWReleaseNum=0),"Available","Not Supported")) -> Available | N6: =IF(A6="","",IF(TcRelease="Any","Available",IF(OR(AND(TcReleaseNum>=VLOOKUP(AWReleaseNum,MinVerInfo,3,FALSE),TcReleaseNum<=VLOOKUP(AWReleaseNum,MinVerInfo,4,FALSE)),AND(TcReleaseNum>=VLOOKUP(AWReleaseNum,MinVerInfo,5,FALSE),TcReleaseNum<=VLOOKUP(AWReleaseNum,MinVerInfo,6,FALSE))),"Available","Not Supported"))) -> Available | O6: =IF(TcReleaseNum<P6,"Not Supported","Available") -> Available | P6: {=_xlfn.SWITCH(TcBaseVer, 14, K6, 13, J6, 12, I6, 11, IFERROR(VLOOKUP(H6,Table2[#All],3,FALSE),"N/A"),0)} -> 0 | Q6: =IF(TcBaseVer=0,M6,IF(AND(N6="Available",M6="Available",O6="Available"),"Available",IF(M6="","","Not Supported"))) -> Available | R6: =IF(A6>=AWCurrentRel, "Future",Q6) -> Available | S6: =HYPERLINK(U6,T6) -> Not Available | T6: =IFERROR(VLOOKUP(CONCATENATE($B6,"_",$A6),Table4[#All],5,FALSE),"Not Available") -> Not Available | U6: =IFERROR(VLOOKUP(CONCATENATE(B6,"_",A6),Table4[#All],6,FALSE),"")
A7: =IF(OR('Raw Data'!A29=0,'Raw Data'!A29="Delete"),"",'Raw Data'!A29) -> 2 | B7: =IF(OR('Raw Data'!B29=0,'Raw Data'!B29="Delete"),"",'Raw Data'!B29) -> Foundation | C7: =IF(OR('Raw Data'!C29=0,'Raw Data'!C29="Delete"),"",'Raw Data'!C29) -> Usability | D7: =IF(OR('Raw Data'!D29=0,'Raw Data'!D29="Delete"),"",'Raw Data'!D29) -> Platform - Active Workspace Framework - Usability | E7: =IF(OR('Raw Data'!E29=0,'Raw Data'!E29="Delete"),"",'Raw Data'!E29) -> Create Item | F7: {=_xlfn.SWITCH(ROUND(VLOOKUP(A7,Table1[#All],3),0),11,H7,12,I7,13,J7,14,K7,"N/A")} -> 13 | G7: {=_xlfn.SWITCH(ROUND(VLOOKUP(A7,Table1[#All],5),0),11,H7,12,I7,13,J7,14,K7,"N/A")} -> 14 | H7: =IF(OR('Raw Data'!H29=0,'Raw Data'!H29="Delete"),"",'Raw Data'!H29) -> 13 | I7: =IF(OR('Raw Data'!I29=0,'Raw Data'!I29="Delete"),"",'Raw Data'!I29) -> 14 | J7: =IF(OR('Raw Data'!J29=0,'Raw Data'!J29="Delete"),"",'Raw Data'!J29) | K7: =IF(OR('Raw Data'!K29=0,'Raw Data'!K29="Delete"),"",'Raw Data'!K29) | L7: =R7 -> Available | M7: =IF(A7="","",IF(OR(AWReleaseNum>=A7,AWReleaseNum=0),"Available","Not Supported")) -> Available | N7: =IF(A7="","",IF(TcRelease="Any","Available",IF(OR(AND(TcReleaseNum>=VLOOKUP(AWReleaseNum,MinVerInfo,3,FALSE),TcReleaseNum<=VLOOKUP(AWReleaseNum,MinVerInfo,4,FALSE)),AND(TcReleaseNum>=VLOOKUP(AWReleaseNum,MinVerInfo,5,FALSE),TcReleaseNum<=VLOOKUP(AWReleaseNum,MinVerInfo,6,FALSE))),"Available","Not Supported"))) -> Available | O7: =IF(TcReleaseNum<P7,"Not Supported","Available") -> Available | P7: {=_xlfn.SWITCH(TcBaseVer, 14, K7, 13, J7, 12, I7, 11, IFERROR(VLOOKUP(H7,Table2[#All],3,FALSE),"N/A"),0)} -> 0 | Q7: =IF(TcBaseVer=0,M7,IF(AND(N7="Available",M7="Available",O7="Available"),"Available",IF(M7="","","Not Supported"))) -> Available | R7: =IF(A7>=AWCurrentRel, "Future",Q7) -> Available | S7: =HYPERLINK(U7,T7) -> Not Available | T7: =IFERROR(VLOOKUP(CONCATENATE($B7,"_",$A7),Table4[#All],5,FALSE),"Not Available") -> Not Available | U7: =IFERROR(VLOOKUP(CONCATENATE(B7,"_",A7),Table4[#All],6,FALSE),"")
A8: =IF(OR('Raw Data'!A30=0,'Raw Data'!A30="Delete"),"",'Raw Data'!A30) -> 2 | B8: =IF(OR('Raw Data'!B30=0,'Raw Data'!B30="Delete"),"",'Raw Data'!B30) -> Foundation | C8: =IF(OR('Raw Data'!C30=0,'Raw Data'!C30="Delete"),"",'Raw Data'!C30) -> Usability | D8: =IF(OR('Raw Data'!D30=0,'Raw Data'!D30="Delete"),"",'Raw Data'!D30) -> Platform - Active Workspace Framework - Usability | E8: =IF(OR('Raw Data'!E30=0,'Raw Data'!E30="Delete"),"",'Raw Data'!E30) -> Create Folder | F8: {=_xlfn.SWITCH(ROUND(VLOOKUP(A8,Table1[#All],3),0),11,H8,12,I8,13,J8,14,K8,"N/A")} -> 13 | G8: {=_xlfn.SWITCH(ROUND(VLOOKUP(A8,Table1[#All],5),0),11,H8,12,I8,13,J8,14,K8,"N/A")} -> 14 | H8: =IF(OR('Raw Data'!H30=0,'Raw Data'!H30="Delete"),"",'Raw Data'!H30) -> 13 | I8: =IF(OR('Raw Data'!I30=0,'Raw Data'!I30="Delete"),"",'Raw Data'!I30) -> 14 | J8: =IF(OR('Raw Data'!J30=0,'Raw Data'!J30="Delete"),"",'Raw Data'!J30) | K8: =IF(OR('Raw Data'!K30=0,'Raw Data'!K30="Delete"),"",'Raw Data'!K30) | L8: =R8 -> Available | M8: =IF(A8="","",IF(OR(AWReleaseNum>=A8,AWReleaseNum=0),"Available","Not Supported")) -> Available | N8: =IF(A8="","",IF(TcRelease="Any","Available",IF(OR(AND(TcReleaseNum>=VLOOKUP(AWReleaseNum,MinVerInfo,3,FALSE),TcReleaseNum<=VLOOKUP(AWReleaseNum,MinVerInfo,4,FALSE)),AND(TcReleaseNum>=VLOOKUP(AWReleaseNum,MinVerInfo,5,FALSE),TcReleaseNum<=VLOOKUP(AWReleaseNum,MinVerInfo,6,FALSE))),"Available","Not Supported"))) -> Available | O8: =IF(TcReleaseNum<P8,"Not Supported","Available") -> Available | P8: {=_xlfn.SWITCH(TcBaseVer, 14, K8, 13, J8, 12, I8, 11, IFERROR(VLOOKUP(H8,Table2[#All],3,FALSE),"N/A"),0)} -> 0 | Q8: =IF(TcBaseVer=0,M8,IF(AND(N8="Available",M8="Available",O8="Available"),"Available",IF(M8="","","Not Supported"))) -> Available | R8: =IF(A8>=AWCurrentRel, "Future",Q8) -> Available | S8: =HYPERLINK(U8,T8) -> Not Available | T8: =IFERROR(VLOOKUP(CONCATENATE($B8,"_",$A8),Table4[#All],5,FALSE),"Not Available") -> Not Available | U8: =IFERROR(VLOOKUP(CONCATENATE(B8,"_",A8),Table4[#All],6,FALSE),"")
A9: =IF(OR('Raw Data'!A31=0,'Raw Data'!A31="Delete"),"",'Raw Data'!A31) -> 2 | B9: =IF(OR('Raw Data'!B31=0,'Raw Data'!B31="Delete"),"",'Raw Data'!B31) -> Foundation | C9: =IF(OR('Raw Data'!C31=0,'Raw Data'!C31="Delete"),"",'Raw Data'!C31) -> Usability | D9: =IF(OR('Raw Data'!D31=0,'Raw Data'!D31="Delete"),"",'Raw Data'!D31) -> Platform - Active Workspace Framework - Usability | E9: =IF(OR('Raw Data'!E31=0,'Raw Data'!E31="Delete"),"",'Raw Data'!E31) -> Create File (w/Upload) | F9: {=_xlfn.SWITCH(ROUND(VLOOKUP(A9,Table1[#All],3),0),11,H9,12,I9,13,J9,14,K9,"N/A")} -> 13 | G9: {=_xlfn.SWITCH(ROUND(VLOOKUP(A9,Table1[#All],5),0),11,H9,12,I9,13,J9,14,K9,"N/A")} -> 14 | H9: =IF(OR('Raw Data'!H31=0,'Raw Data'!H31="Delete"),"",'Raw Data'!H31) -> 13 | I9: =IF(OR('Raw Data'!I31=0,'Raw Data'!I31="Delete"),"",'Raw Data'!I31) -> 14 | J9: =IF(OR('Raw Data'!J31=0,'Raw Data'!J31="Delete"),"",'Raw Data'!J31) | K9: =IF(OR('Raw Data'!K31=0,'Raw Data'!K31="Delete"),"",'Raw Data'!K31) | L9: =R9 -> Available | M9: =IF(A9="","",IF(OR(AWReleaseNum>=A9,AWReleaseNum=0),"Available","Not Supported")) -> Available | N9: =IF(A9="","",IF(TcRelease="Any","Available",IF(OR(AND(TcReleaseNum>=VLOOKUP(AWReleaseNum,MinVerInfo,3,FALSE),TcReleaseNum<=VLOOKUP(AWReleaseNum,MinVerInfo,4,FALSE)),AND(TcReleaseNum>=VLOOKUP(AWReleaseNum,MinVerInfo,5,FALSE),TcReleaseNum<=VLOOKUP(AWReleaseNum,MinVerInfo,6,FALSE))),"Available","Not Supported"))) -> Available | O9: =IF(TcReleaseNum<P9,"Not Supported","Available") -> Available | P9: {=_xlfn.SWITCH(TcBaseVer, 14, K9, 13, J9, 12, I9, 11, IFERROR(VLOOKUP(H9,Table2[#All],3,FALSE),"N/A"),0)} -> 0 | Q9: =IF(TcBaseVer=0,M9,IF(AND(N9="Available",M9="Available",O9="Available"),"Available",IF(M9="","","Not Supported"))) -> Available | R9: =IF(A9>=AWCurrentRel, "Future",Q9) -> Available | S9: =HYPERLINK(U9,T9) -> Not Available | T9: =IFERROR(VLOOKUP(CONCATENATE($B9,"_",$A9),Table4[#All],5,FALSE),"Not Available") -> Not Available | U9: =IFERROR(VLOOKUP(CONCATENATE(B9,"_",A9),Table4[#All],6,FALSE),"")
A10: =IF(OR('Raw Data'!A32=0,'Raw Data'!A32="Delete"),"",'Raw Data'!A32) -> 2 | B10: =IF(OR('Raw Data'!B32=0,'Raw Data'!B32="Delete"),"",'Raw Data'!B32) -> Foundation | C10: =IF(OR('Raw Data'!C32=0,'Raw Data'!C32="Delete"),"",'Raw Data'!C32) -> Usability | D10: =IF(OR('Raw Data'!D32=0,'Raw Data'!D32="Delete"),"",'Raw Data'!D32) -> Platform - Active Workspace Framework - Usability | E10: =IF(OR('Raw Data'!E32=0,'Raw Data'!E32="Delete"),"",'Raw Data'!E32) -> Create change in context (or not) | F10: {=_xlfn.SWITCH(ROUND(VLOOKUP(A10,Table1[#All],3),0),11,H10,12,I10,13,J10,14,K10,"N/A")} -> 13 | G10: {=_xlfn.SWITCH(ROUND(VLOOKUP(A10,Table1[#All],5),0),11,H10,12,I10,13,J10,14,K10,"N/A")} -> 14 | H10: =IF(OR('Raw Data'!H32=0,'Raw Data'!H32="Delete"),"",'Raw Data'!H32) -> 13 | I10: =IF(OR('Raw Data'!I32=0,'Raw Data'!I32="Delete"),"",'Raw Data'!I32) -> 14 | J10: =IF(OR('Raw Data'!J32=0,'Raw Data'!J32="Delete"),"",'Raw Data'!J32) | K10: =IF(OR('Raw Data'!K32=0,'Raw Data'!K32="Delete"),"",'Raw Data'!K32) | L10: =R10 -> Available | M10: =IF(A10="","",IF(OR(AWReleaseNum>=A10,AWReleaseNum=0),"Available","Not Supported")) -> Available | N10: =IF(A10="","",IF(TcRelease="Any","Available",IF(OR(AND(TcReleaseNum>=VLOOKUP(AWReleaseNum,MinVerInfo,3,FALSE),TcReleaseNum<=VLOOKUP(AWReleaseNum,MinVerInfo,4,FALSE)),AND(TcReleaseNum>=VLOOKUP(AWReleaseNum,MinVerInfo,5,FALSE),TcReleaseNum<=VLOOKUP(AWReleaseNum,MinVerInfo,6,FALSE))),"Available","Not Supported"))) -> Available | O10: =IF(TcReleaseNum<P10,"Not Supported","Available") -> Available | P10: {=_xlfn.SWITCH(TcBaseVer, 14, K10, 13, J10, 12, I10, 11, IFERROR(VLOOKUP(H10,Table2[#All],3,FALSE),"N/A"),0)} -> 0 | Q10: =IF(TcBaseVer=0,M10,IF(AND(N10="Available",M10="Available",O10="Available"),"Available",IF(M10="","","Not Supported"))) -> Available | R10: =IF(A10>=AWCurrentRel, "Future",Q10) -> Available | S10: =HYPERLINK(U10,T10) -> Not Available | T10: =IFERROR(VLOOKUP(CONCATENATE($B10,"_",$A10),Table4[#All],5,FALSE),"Not Available") -> Not Available | U10: =IFERROR(VLOOKUP(CONCATENATE(B10,"_",A10),Table4[#All],6,FALSE),"")
A11: =IF(OR('Raw Data'!A33=0,'Raw Data'!A33="Delete"),"",'Raw Data'!A33) -> 2 | B11: =IF(OR('Raw Data'!B33=0,'Raw Data'!B33="Delete"),"",'Raw Data'!B33) -> Foundation | C11: =IF(OR('Raw Data'!C33=0,'Raw Data'!C33="Delete"),"",'Raw Data'!C33) -> Usability | D11: =IF(OR('Raw Data'!D33=0,'Raw Data'!D33="Delete"),"",'Raw Data'!D33) -> Platform - Active Workspace Framework - Usability | E11: =IF(OR('Raw Data'!E33=0,'Raw Data'!E33="Delete"),"",'Raw Data'!E33) -> Revise | F11: {=_xlfn.SWITCH(ROUND(VLOOKUP(A11,Table1[#All],3),0),11,H11,12,I11,13,J11,14,K11,"N/A")} -> 13 | G11: {=_xlfn.SWITCH(ROUND(VLOOKUP(A11,Table1[#All],5),0),11,H11,12,I11,13,J11,14,K11,"N/A")} -> 14 | H11: =IF(OR('Raw Data'!H33=0,'Raw Data'!H33="Delete"),"",'Raw Data'!H33) -> 13 | I11: =IF(OR('Raw Data'!I33=0,'Raw Data'!I33="Delete"),"",'Raw Data'!I33) -> 14 | J11: =IF(OR('Raw Data'!J33=0,'Raw Data'!J33="Delete"),"",'Raw Data'!J33) | K11: =IF(OR('Raw Data'!K33=0,'Raw Data'!K33="Delete"),"",'Raw Data'!K33) | L11: =R11 -> Available | M11: =IF(A11="","",IF(OR(AWReleaseNum>=A11,AWReleaseNum=0),"Available","Not Supported")) -> Available | N11: =IF(A11="","",IF(TcRelease="Any","Available",IF(OR(AND(TcReleaseNum>=VLOOKUP(AWReleaseNum,MinVerInfo,3,FALSE),TcReleaseNum<=VLOOKUP(AWReleaseNum,MinVerInfo,4,FALSE)),AND(TcReleaseNum>=VLOOKUP(AWReleaseNum,MinVerInfo,5,FALSE),TcReleaseNum<=VLOOKUP(AWReleaseNum,MinVerInfo,6,FALSE))),"Available","Not Supported"))) -> Available | O11: =IF(TcReleaseNum<P11,"Not Supported","Available") -> Available | P11: {=_xlfn.SWITCH(TcBaseVer, 14, K11, 13, J11, 12, I11, 11, IFERROR(VLOOKUP(H11,Table2[#All],3,FALSE),"N/A"),0)} -> 0 | Q11: =IF(TcBaseVer=0,M11,IF(AND(N11="Available",M11="Available",O11="Available"),"Available",IF(M11="","","Not Supported"))) -> Available | R11: =IF(A11>=AWCurrentRel, "Future",Q11) -> Available | S11: =HYPERLINK(U11,T11) -> Not Available | T11: =IFERROR(VLOOKUP(CONCATENATE($B11,"_",$A11),Table4[#All],5,FALSE),"Not Available") -> Not Available | U11: =IFERROR(VLOOKUP(CONCATENATE(B11,"_",A11),Table4[#All],6,FALSE),"")
A12: =IF(OR('Raw Data'!A34=0,'Raw Data'!A34="Delete"),"",'Raw Data'!A34) -> 2 | B12: =IF(OR('Raw Data'!B34=0,'Raw Data'!B34="Delete"),"",'Raw Data'!B34) -> Foundation | C12: =IF(OR('Raw Data'!C34=0,'Raw Data'!C34="Delete"),"",'Raw Data'!C34) -> Usability | D12: =IF(OR('Raw Data'!D34=0,'Raw Data'!D34="Delete"),"",'Raw Data'!D34) -> Platform - Active Workspace Framework - Usability | E12: =IF(OR('Raw Data'!E34=0,'Raw Data'!E34="Delete"),"",'Raw Data'!E34) -> Context Setting – Project, Group/Role, Revision Rule | F12: {=_xlfn.SWITCH(ROUND(VLOOKUP(A12,Table1[#All],3),0),11,H12,12,I12,13,J12,14,K12,"N/A")} -> 13 | G12: {=_xlfn.SWITCH(ROUND(VLOOKUP(A12,Table1[#All],5),0),11,H12,12,I12,13,J12,14,K12,"N/A")} -> 14 | H12: =IF(OR('Raw Data'!H34=0,'Raw Data'!H34="Delete"),"",'Raw Data'!H34) -> 13 | I12: =IF(OR('Raw Data'!I34=0,'Raw Data'!I34="Delete"),"",'Raw Data'!I34) -> 14 | J12: =IF(OR('Raw Data'!J34=0,'Raw Data'!J34="Delete"),"",'Raw Data'!J34) | K12: =IF(OR('Raw Data'!K34=0,'Raw Data'!K34="Delete"),"",'Raw Data'!K34) | L12: =R12 -> Available | M12: =IF(A12="","",IF(OR(AWReleaseNum>=A12,AWReleaseNum=0),"Available","Not Supported")) -> Available | N12: =IF(A12="","",IF(TcRelease="Any","Available",IF(OR(AND(TcReleaseNum>=VLOOKUP(AWReleaseNum,MinVerInfo,3,FALSE),TcReleaseNum<=VLOOKUP(AWReleaseNum,MinVerInfo,4,FALSE)),AND(TcReleaseNum>=VLOOKUP(AWReleaseNum,MinVerInfo,5,FALSE),TcReleaseNum<=VLOOKUP(AWReleaseNum,MinVerInfo,6,FALSE))),"Available","Not Supported"))) -> Available | O12: =IF(TcReleaseNum<P12,"Not Supported","Available") -> Available | P12: {=_xlfn.SWITCH(TcBaseVer, 14, K12, 13, J12, 12, I12, 11, IFERROR(VLOOKUP(H12,Table2[#All],3,FALSE),"N/A"),0)} -> 0 | Q12: =IF(TcBaseVer=0,M12,IF(AND(N12="Available",M12="Available",O12="Available"),"Available",IF(M12="","","Not Supported"))) -> Available | R12: =IF(A12>=AWCurrentRel, "Future",Q12) -> Available | S12: =HYPERLINK(U12,T12) -> Not Available | T12: =IFERROR(VLOOKUP(CONCATENATE($B12,"_",$A12),Table4[#All],5,FALSE),"Not Available") -> Not Available | U12: =IFERROR(VLOOKUP(CONCATENATE(B12,"_",A12),Table4[#All],6,FALSE),"")
A13: =IF(OR('Raw Data'!A35=0,'Raw Data'!A35="Delete"),"",'Raw Data'!A35) -> 2 | B13: =IF(OR('Raw Data'!B35=0,'Raw Data'!B35="Delete"),"",'Raw Data'!B35) -> Foundation | C13: =IF(OR('Raw Data'!C35=0,'Raw Data'!C35="Delete"),"",'Raw Data'!C35) -> Usability | D13: =IF(OR('Raw Data'!D35=0,'Raw Data'!D35="Delete"),"",'Raw Data'!D35) -> Platform - Active Workspace Framework - Usability | E13: =IF(OR('Raw Data'!E35=0,'Raw Data'!E35="Delete"),"",'Raw Data'!E35) -> Stacked Commands | F13: {=_xlfn.SWITCH(ROUND(VLOOKUP(A13,Table1[#All],3),0),11,H13,12,I13,13,J13,14,K13,"N/A")} -> 13 | G13: {=_xlfn.SWITCH(ROUND(VLOOKUP(A13,Table1[#All],5),0),11,H13,12,I13,13,J13,14,K13,"N/A")} -> 14 | H13: =IF(OR('Raw Data'!H35=0,'Raw Data'!H35="Delete"),"",'Raw Data'!H35) -> 13 | I13: =IF(OR('Raw Data'!I35=0,'Raw Data'!I35="Delete"),"",'Raw Data'!I35) -> 14 | J13: =IF(OR('Raw Data'!J35=0,'Raw Data'!J35="Delete"),"",'Raw Data'!J35) | K13: =IF(OR('Raw Data'!K35=0,'Raw Data'!K35="Delete"),"",'Raw Data'!K35) | L13: =R13 -> Available | M13: =IF(A13="","",IF(OR(AWReleaseNum>=A13,AWReleaseNum=0),"Available","Not Supported")) -> Available | N13: =IF(A13="","",IF(TcRelease="Any","Available",IF(OR(AND(TcReleaseNum>=VLOOKUP(AWReleaseNum,MinVerInfo,3,FALSE),TcReleaseNum<=VLOOKUP(AWReleaseNum,MinVerInfo,4,FALSE)),AND(TcReleaseNum>=VLOOKUP(AWReleaseNum,MinVerInfo,5,FALSE),TcReleaseNum<=VLOOKUP(AWReleaseNum,MinVerInfo,6,FALSE))),"Available","Not Supported"))) -> Available | O13: =IF(TcReleaseNum<P13,"Not Supported","Available") -> Available | P13: {=_xlfn.SWITCH(TcBaseVer, 14, K13, 13, J13, 12, I13, 11, IFERROR(VLOOKUP(H13,Table2[#All],3,FALSE),"N/A"),0)} -> 0 | Q13: =IF(TcBaseVer=0,M13,IF(AND(N13="Available",M13="Available",O13="Available"),"Available",IF(M13="","","Not Supported"))) -> Available | R13: =IF(A13>=AWCurrentRel, "Future",Q13) -> Available | S13: =HYPERLINK(U13,T13) -> Not Available | T13: =IFERROR(VLOOKUP(CONCATENATE($B13,"_",$A13),Table4[#All],5,FALSE),"Not Available") -> Not Available | U13: =IFERROR(VLOOKUP(CONCATENATE(B13,"_",A13),Table4[#All],6,FALSE),"")
A14: =IF(OR('Raw Data'!A36=0,'Raw Data'!A36="Delete"),"",'Raw Data'!A36) -> 2 | B14: =IF(OR('Raw Data'!B36=0,'Raw Data'!B36="Delete"),"",'Raw Data'!B36) -> Foundation | C14: =IF(OR('Raw Data'!C36=0,'Raw Data'!C36="Delete"),"",'Raw Data'!C36) -> Usability | D14: =IF(OR('Raw Data'!D36=0,'Raw Data'!D36="Delete"),"",'Raw Data'!D36) -> Platform - Active Workspace Framework - Usability | E14: =IF(OR('Raw Data'!E36=0,'Raw Data'!E36="Delete"),"",'Raw Data'!E36) -> Property Editing | F14: {=_xlfn.SWITCH(ROUND(VLOOKUP(A14,Table1[#All],3),0),11,H14,12,I14,13,J14,14,K14,"N/A")} -> 13 | G14: {=_xlfn.SWITCH(ROUND(VLOOKUP(A14,Table1[#All],5),0),11,H14,12,I14,13,J14,14,K14,"N/A")} -> 14 | H14: =IF(OR('Raw Data'!H36=0,'Raw Data'!H36="Delete"),"",'Raw Data'!H36) -> 13 | I14: =IF(OR('Raw Data'!I36=0,'Raw Data'!I36="Delete"),"",'Raw Data'!I36) -> 14 | J14: =IF(OR('Raw Data'!J36=0,'Raw Data'!J36="Delete"),"",'Raw Data'!J36) | K14: =IF(OR('Raw Data'!K36=0,'Raw Data'!K36="Delete"),"",'Raw Data'!K36) | L14: =R14 -> Available | M14: =IF(A14="","",IF(OR(AWReleaseNum>=A14,AWReleaseNum=0),"Available","Not Supported")) -> Available | N14: =IF(A14="","",IF(TcRelease="Any","Available",IF(OR(AND(TcReleaseNum>=VLOOKUP(AWReleaseNum,MinVerInfo,3,FALSE),TcReleaseNum<=VLOOKUP(AWReleaseNum,MinVerInfo,4,FALSE)),AND(TcReleaseNum>=VLOOKUP(AWReleaseNum,MinVerInfo,5,FALSE),TcReleaseNum<=VLOOKUP(AWReleaseNum,MinVerInfo,6,FALSE))),"Available","Not Supported"))) -> Available | O14: =IF(TcReleaseNum<P14,"Not Supported","Available") -> Available | P14: {=_xlfn.SWITCH(TcBaseVer, 14, K14, 13, J14, 12, I14, 11, IFERROR(VLOOKUP(H14,Table2[#All],3,FALSE),"N/A"),0)} -> 0 | Q14: =IF(TcBaseVer=0,M14,IF(AND(N14="Available",M14="Available",O14="Available"),"Available",IF(M14="","","Not Supported"))) -> Available | R14: =IF(A14>=AWCurrentRel, "Future",Q14) -> Available | S14: =HYPERLINK(U14,T14) -> Not Available | T14: =IFERROR(VLOOKUP(CONCATENATE($B14,"_",$A14),Table4[#All],5,FALSE),"Not Available") -> Not Available | U14: =IFERROR(VLOOKUP(CONCATENATE(B14,"_",A14),Table4[#All],6,FALSE),"")
A15: =IF(OR('Raw Data'!A37=0,'Raw Data'!A37="Delete"),"",'Raw Data'!A37) -> 2 | B15: =IF(OR('Raw Data'!B37=0,'Raw Data'!B37="Delete"),"",'Raw Data'!B37) -> Foundation | C15: =IF(OR('Raw Data'!C37=0,'Raw Data'!C37="Delete"),"",'Raw Data'!C37) -> Usability | D15: =IF(OR('Raw Data'!D37=0,'Raw Data'!D37="Delete"),"",'Raw Data'!D37) -> Platform - Active Workspace Framework - Usability | E15: =IF(OR('Raw Data'!E37=0,'Raw Data'!E37="Delete"),"",'Raw Data'!E37) -> Open Rich Client on selected Object | F15: {=_xlfn.SWITCH(ROUND(VLOOKUP(A15,Table1[#All],3),0),11,H15,12,I15,13,J15,14,K15,"N/A")} -> 13 | G15: {=_xlfn.SWITCH(ROUND(VLOOKUP(A15,Table1[#All],5),0),11,H15,12,I15,13,J15,14,K15,"N/A")} -> 14 | H15: =IF(OR('Raw Data'!H37=0,'Raw Data'!H37="Delete"),"",'Raw Data'!H37) -> 13 | I15: =IF(OR('Raw Data'!I37=0,'Raw Data'!I37="Delete"),"",'Raw Data'!I37) -> 14 | J15: =IF(OR('Raw Data'!J37=0,'Raw Data'!J37="Delete"),"",'Raw Data'!J37) | K15: =IF(OR('Raw Data'!K37=0,'Raw Data'!K37="Delete"),"",'Raw Data'!K37) | L15: =R15 -> Available | M15: =IF(A15="","",IF(OR(AWReleaseNum>=A15,AWReleaseNum=0),"Available","Not Supported")) -> Available | N15: =IF(A15="","",IF(TcRelease="Any","Available",IF(OR(AND(TcReleaseNum>=VLOOKUP(AWReleaseNum,MinVerInfo,3,FALSE),TcReleaseNum<=VLOOKUP(AWReleaseNum,MinVerInfo,4,FALSE)),AND(TcReleaseNum>=VLOOKUP(AWReleaseNum,MinVerInfo,5,FALSE),TcReleaseNum<=VLOOKUP(AWReleaseNum,MinVerInfo,6,FALSE))),"Available","Not Supported"))) -> Available | O15: =IF(TcReleaseNum<P15,"Not Supported","Available") -> Available | P15: {=_xlfn.SWITCH(TcBaseVer, 14, K15, 13, J15, 12, I15, 11, IFERROR(VLOOKUP(H15,Table2[#All],3,FALSE),"N/A"),0)} -> 0 | Q15: =IF(TcBaseVer=0,M15,IF(AND(N15="Available",M15="Available",O15="Available"),"Available",IF(M15="","","Not Supported"))) -> Available | R15: =IF(A15>=AWCurrentRel, "Future",Q15) -> Available | S15: =HYPERLINK(U15,T15) -> Not Available | T15: =IFERROR(VLOOKUP(CONCATENATE($B15,"_",$A15),Table4[#All],5,FALSE),"Not Available") -> Not Available | U15: =IFERROR(VLOOKUP(CONCATENATE(B15,"_",A15),Table4[#All],6,FALSE),"")
A16: =IF(OR('Raw Data'!A38=0,'Raw Data'!A38="Delete"),"",'Raw Data'!A38) -> 2 | B16: =IF(OR('Raw Data'!B38=0,'Raw Data'!B38="Delete"),"",'Raw Data'!B38) -> Foundation | C16: =IF(OR('Raw Data'!C38=0,'Raw Data'!C38="Delete"),"",'Raw Data'!C38) -> Usability | D16: =IF(OR('Raw Data'!D38=0,'Raw Data'!D38="Delete"),"",'Raw Data'!D38) -> Platform - Active Workspace Framework - Usability | E16: =IF(OR('Raw Data'!E38=0,'Raw Data'!E38="Delete"),"",'Raw Data'!E38) -> Object Summary View | F16: {=_xlfn.SWITCH(ROUND(VLOOKUP(A16,Table1[#All],3),0),11,H16,12,I16,13,J16,14,K16,"N/A")} -> 13 | G16: {=_xlfn.SWITCH(ROUND(VLOOKUP(A16,Table1[#All],5),0),11,H16,12,I16,13,J16,14,K16,"N/A")} -> 14 | H16: =IF(OR('Raw Data'!H38=0,'Raw Data'!H38="Delete"),"",'Raw Data'!H38) -> 13 | I16: =IF(OR('Raw Data'!I38=0,'Raw Data'!I38="Delete"),"",'Raw Data'!I38) -> 14 | J16: =IF(OR('Raw Data'!J38=0,'Raw Data'!J38="Delete"),"",'Raw Data'!J38) | K16: =IF(OR('Raw Data'!K38=0,'Raw Data'!K38="Delete"),"",'Raw Data'!K38) | L16: =R16 -> Available | M16: =IF(A16="","",IF(OR(AWReleaseNum>=A16,AWReleaseNum=0),"Available","Not Supported")) -> Available | N16: =IF(A16="","",IF(TcRelease="Any","Available",IF(OR(AND(TcReleaseNum>=VLOOKUP(AWReleaseNum,MinVerInfo,3,FALSE),TcReleaseNum<=VLOOKUP(AWReleaseNum,MinVerInfo,4,FALSE)),AND(TcReleaseNum>=VLOOKUP(AWReleaseNum,MinVerInfo,5,FALSE),TcReleaseNum<=VLOOKUP(AWReleaseNum,MinVerInfo,6,FALSE))),"Available","Not Supported"))) -> Available | O16: =IF(TcReleaseNum<P16,"Not Supported","Available") -> Available | P16: {=_xlfn.SWITCH(TcBaseVer, 14, K16, 13, J16, 12, I16, 11, IFERROR(VLOOKUP(H16,Table2[#All],3,FALSE),"N/A"),0)} -> 0 | Q16: =IF(TcBaseVer=0,M16,IF(AND(N16="Available",M16="Available",O16="Available"),"Available",IF(M16="","","Not Supported"))) -> Available | R16: =IF(A16>=AWCurrentRel, "Future",Q16) -> Available | S16: =HYPERLINK(U16,T16) -> Not Available | T16: =IFERROR(VLOOKUP(CONCATENATE($B16,"_",$A16),Table4[#All],5,FALSE),"Not Available") -> Not Available | U16: =IFERROR(VLOOKUP(CONCATENATE(B16,"_",A16),Table4[#All],6,FALSE),"")
A17: =IF(OR('Raw Data'!A39=0,'Raw Data'!A39="Delete"),"",'Raw Data'!A39) -> 2 | B17: =IF(OR('Raw Data'!B39=0,'Raw Data'!B39="Delete"),"",'Raw Data'!B39) -> Foundation | C17: =IF(OR('Raw Data'!C39=0,'Raw Data'!C39="Delete"),"",'Raw Data'!C39) -> Usability | D17: =IF(OR('Raw Data'!D39=0,'Raw Data'!D39="Delete"),"",'Raw Data'!D39) -> Platform - Active Workspace Framework - Usability | E17: =IF(OR('Raw Data'!E39=0,'Raw Data'!E39="Delete"),"",'Raw Data'!E39) -> Multiple smart tabs | F17: {=_xlfn.SWITCH(ROUND(VLOOKUP(A17,Table1[#All],3),0),11,H17,12,I17,13,J17,14,K17,"N/A")} -> 13 | G17: {=_xlfn.SWITCH(ROUND(VLOOKUP(A17,Table1[#All],5),0),11,H17,12,I17,13,J17,14,K17,"N/A")} -> 14 | H17: =IF(OR('Raw Data'!H39=0,'Raw Data'!H39="Delete"),"",'Raw Data'!H39) -> 13 | I17: =IF(OR('Raw Data'!I39=0,'Raw Data'!I39="Delete"),"",'Raw Data'!I39) -> 14 | J17: =IF(OR('Raw Data'!J39=0,'Raw Data'!J39="Delete"),"",'Raw Data'!J39) | K17: =IF(OR('Raw Data'!K39=0,'Raw Data'!K39="Delete"),"",'Raw Data'!K39) | L17: =R17 -> Available | M17: =IF(A17="","",IF(OR(AWReleaseNum>=A17,AWReleaseNum=0),"Available","Not Supported")) -> Available | N17: =IF(A17="","",IF(TcRelease="Any","Available",IF(OR(AND(TcReleaseNum>=VLOOKUP(AWReleaseNum,MinVerInfo,3,FALSE),TcReleaseNum<=VLOOKUP(AWReleaseNum,MinVerInfo,4,FALSE)),AND(TcReleaseNum>=VLOOKUP(AWReleaseNum,MinVerInfo,5,FALSE),TcReleaseNum<=VLOOKUP(AWReleaseNum,MinVerInfo,6,FALSE))),"Available","Not Supported"))) -> Available | O17: =IF(TcReleaseNum<P17,"Not Supported","Available") -> Available | P17: {=_xlfn.SWITCH(TcBaseVer, 14, K17, 13, J17, 12, I17, 11, IFERROR(VLOOKUP(H17,Table2[#All],3,FALSE),"N/A"),0)} -> 0 | Q17: =IF(TcBaseVer=0,M17,IF(AND(N17="Available",M17="Available",O17="Available"),"Available",IF(M17="","","Not Supported"))) -> Available | R17: =IF(A17>=AWCurrentRel, "Future",Q17) -> Available | S17: =HYPERLINK(U17,T17) -> Not Available | T17: =IFERROR(VLOOKUP(CONCATENATE($B17,"_",$A17),Table4[#All],5,FALSE),"Not Available") -> Not Available | U17: =IFERROR(VLOOKUP(CONCATENATE(B17,"_",A17),Table4[#All],6,FALSE),"")
... A28: =IF(OR('Raw Data'!A50=0,'Raw Data'!A50="Delete"),"",'Raw Data'!A50) -> 2 | B28: =IF(OR('Raw Data'!B50=0,'Raw Data'!B50="Delete"),"",'Raw Data'!B50) -> Plan | C28: =IF(OR('Raw Data'!C50=0,'Raw Data'!C50="Delete"),"",'Raw Data'!C50) -> Requirements | D28: =IF(OR('Raw Data'!D50=0,'Raw Data'!D50="Delete"),"",'Raw Data'!D50) -> Requirements Management | E28: =IF(OR('Raw Data'!E50=0,'Raw Data'!E50="Delete"),"",'Raw Data'!E50) -> Traceability tracking | F28: {=_xlfn.SWITCH(ROUND(VLOOKUP(A28,Table1[#All],3),0),11,H28,12,I28,13,J28,14,K28,"N/A")} -> 13 | G28: {=_xlfn.SWITCH(ROUND(VLOOKUP(A28,Table1[#All],5),0),11,H28,12,I28,13,J28,14,K28,"N/A")} -> 14 | H28: =IF(OR('Raw Data'!H50=0,'Raw Data'!H50="Delete"),"",'Raw Data'!H50) -> 13 | I28: =IF(OR('Raw Data'!I50=0,'Raw Data'!I50="Delete"),"",'Raw Data'!I50) -> 14 | J28: =IF(OR('Raw Data'!J50=0,'Raw Data'!J50="Delete"),"",'Raw Data'!J50) | K28: =IF(OR('Raw Data'!K50=0,'Raw Data'!K50="Delete"),"",'Raw Data'!K50) | L28: =R28 -> Available | M28: =IF(A28="","",IF(OR(AWReleaseNum>=A28,AWReleaseNum=0),"Available","Not Supported")) -> Available | N28: =IF(A28="","",IF(TcRelease="Any","Available",IF(OR(AND(TcReleaseNum>=VLOOKUP(AWReleaseNum,MinVerInfo,3,FALSE),TcReleaseNum<=VLOOKUP(AWReleaseNum,MinVerInfo,4,FALSE)),AND(TcReleaseNum>=VLOOKUP(AWReleaseNum,MinVerInfo,5,FALSE),TcReleaseNum<=VLOOKUP(AWReleaseNum,MinVerInfo,6,FALSE))),"Available","Not Supported"))) -> Available | O28: =IF(TcReleaseNum<P28,"Not Supported","Available") -> Available | P28: {=_xlfn.SWITCH(TcBaseVer, 14, K28, 13, J28, 12, I28, 11, IFERROR(VLOOKUP(H28,Table2[#All],3,FALSE),"N/A"),0)} -> 0 | Q28: =IF(TcBaseVer=0,M28,IF(AND(N28="Available",M28="Available",O28="Available"),"Available",IF(M28="","","Not Supported"))) -> Available | R28: =IF(A28>=AWCurrentRel, "Future",Q28) -> Available | S28: =HYPERLINK(U28,T28) -> Not Available | T28: =IFERROR(VLOOKUP(CONCATENATE($B28,"_",$A28),Table4[#All],5,FALSE),"Not Available") -> Not Available | U28: =IFERROR(VLOOKUP(CONCATENATE(B28,"_",A28),Table4[#All],6,FALSE),"")
A29: =IF(OR('Raw Data'!A4=0,'Raw Data'!A4="Delete"),"",'Raw Data'!A4) -> 2 | B29: =IF(OR('Raw Data'!B4=0,'Raw Data'!B4="Delete"),"",'Raw Data'!B4) -> Deliver | C29: =IF(OR('Raw Data'!C4=0,'Raw Data'!C4="Delete"),"",'Raw Data'!C4) -> Analytics | D29: =IF(OR('Raw Data'!D4=0,'Raw Data'!D4="Delete"),"",'Raw Data'!D4) -> Search and Analytics - Search | E29: =IF(OR('Raw Data'!E4=0,'Raw Data'!E4="Delete"),"",'Raw Data'!E4) -> Breadcrumb | F29: {=_xlfn.SWITCH(ROUND(VLOOKUP(A29,Table1[#All],3),0),11,H29,12,I29,13,J29,14,K29,"N/A")} -> 13 | G29: {=_xlfn.SWITCH(ROUND(VLOOKUP(A29,Table1[#All],5),0),11,H29,12,I29,13,J29,14,K29,"N/A")} -> 14 | H29: =IF(OR('Raw Data'!H4=0,'Raw Data'!H4="Delete"),"",'Raw Data'!H4) -> 13 | I29: =IF(OR('Raw Data'!I4=0,'Raw Data'!I4="Delete"),"",'Raw Data'!I4) -> 14 | J29: =IF(OR('Raw Data'!J4=0,'Raw Data'!J4="Delete"),"",'Raw Data'!J4) | K29: =IF(OR('Raw Data'!K4=0,'Raw Data'!K4="Delete"),"",'Raw Data'!K4) | L29: =R29 -> Available | M29: =IF(A29="","",IF(OR(AWReleaseNum>=A29,AWReleaseNum=0),"Available","Not Supported")) -> Available | N29: =IF(A29="","",IF(TcRelease="Any","Available",IF(OR(AND(TcReleaseNum>=VLOOKUP(AWReleaseNum,MinVerInfo,3,FALSE),TcReleaseNum<=VLOOKUP(AWReleaseNum,MinVerInfo,4,FALSE)),AND(TcReleaseNum>=VLOOKUP(AWReleaseNum,MinVerInfo,5,FALSE),TcReleaseNum<=VLOOKUP(AWReleaseNum,MinVerInfo,6,FALSE))),"Available","Not Supported"))) -> Available | O29: =IF(TcReleaseNum<P29,"Not Supported","Available") -> Available | P29: {=_xlfn.SWITCH(TcBaseVer, 14, K29, 13, J29, 12, I29, 11, IFERROR(VLOOKUP(H29,Table2[#All],3,FALSE),"N/A"),0)} -> 0 | Q29: =IF(TcBaseVer=0,M29,IF(AND(N29="Available",M29="Available",O29="Available"),"Available",IF(M29="","","Not Supported"))) -> Available | R29: =IF(A29>=AWCurrentRel, "Future",Q29) -> Available | S29: =HYPERLINK(U29,T29) -> Not Available | T29: =IFERROR(VLOOKUP(CONCATENATE($B29,"_",$A29),Table4[#All],5,FALSE),"Not Available") -> Not Available | U29: =IFERROR(VLOOKUP(CONCATENATE(B29,"_",A29),Table4[#All],6,FALSE),"")
A30: =IF(OR('Raw Data'!A5=0,'Raw Data'!A5="Delete"),"",'Raw Data'!A5) -> 2 | B30: =IF(OR('Raw Data'!B5=0,'Raw Data'!B5="Delete"),"",'Raw Data'!B5) -> Deliver | C30: =IF(OR('Raw Data'!C5=0,'Raw Data'!C5="Delete"),"",'Raw Data'!C5) -> Analytics | D30: =IF(OR('Raw Data'!D5=0,'Raw Data'!D5="Delete"),"",'Raw Data'!D5) -> Search and Analytics - Search | E30: =IF(OR('Raw Data'!E5=0,'Raw Data'!E5="Delete"),"",'Raw Data'!E5) -> Filter results | F30: {=_xlfn.SWITCH(ROUND(VLOOKUP(A30,Table1[#All],3),0),11,H30,12,I30,13,J30,14,K30,"N/A")} -> 13 | G30: {=_xlfn.SWITCH(ROUND(VLOOKUP(A30,Table1[#All],5),0),11,H30,12,I30,13,J30,14,K30,"N/A")} -> 14 | H30: =IF(OR('Raw Data'!H5=0,'Raw Data'!H5="Delete"),"",'Raw Data'!H5) -> 13 | I30: =IF(OR('Raw Data'!I5=0,'Raw Data'!I5="Delete"),"",'Raw Data'!I5) -> 14 | J30: =IF(OR('Raw Data'!J5=0,'Raw Data'!J5="Delete"),"",'Raw Data'!J5) | K30: =IF(OR('Raw Data'!K5=0,'Raw Data'!K5="Delete"),"",'Raw Data'!K5) | L30: =R30 -> Available | M30: =IF(A30="","",IF(OR(AWReleaseNum>=A30,AWReleaseNum=0),"Available","Not Supported")) -> Available | N30: =IF(A30="","",IF(TcRelease="Any","Available",IF(OR(AND(TcReleaseNum>=VLOOKUP(AWReleaseNum,MinVerInfo,3,FALSE),TcReleaseNum<=VLOOKUP(AWReleaseNum,MinVerInfo,4,FALSE)),AND(TcReleaseNum>=VLOOKUP(AWReleaseNum,MinVerInfo,5,FALSE),TcReleaseNum<=VLOOKUP(AWReleaseNum,MinVerInfo,6,FALSE))),"Available","Not Supported"))) -> Available | O30: =IF(TcReleaseNum<P30,"Not Supported","Available") -> Available | P30: {=_xlfn.SWITCH(TcBaseVer, 14, K30, 13, J30, 12, I30, 11, IFERROR(VLOOKUP(H30,Table2[#All],3,FALSE),"N/A"),0)} -> 0 | Q30: =IF(TcBaseVer=0,M30,IF(AND(N30="Available",M30="Available",O30="Available"),"Available",IF(M30="","","Not Supported"))) -> Available | R30: =IF(A30>=AWCurrentRel, "Future",Q30) -> Available | S30: =HYPERLINK(U30,T30) -> Not Available | T30: =IFERROR(VLOOKUP(CONCATENATE($B30,"_",$A30),Table4[#All],5,FALSE),"Not Available") -> Not Available | U30: =IFERROR(VLOOKUP(CONCATENATE(B30,"_",A30),Table4[#All],6,FALSE),"")
A31: =IF(OR('Raw Data'!A6=0,'Raw Data'!A6="Delete"),"",'Raw Data'!A6) -> 2 | B31: =IF(OR('Raw Data'!B6=0,'Raw Data'!B6="Delete"),"",'Raw Data'!B6) -> Deliver | C31: =IF(OR('Raw Data'!C6=0,'Raw Data'!C6="Delete"),"",'Raw Data'!C6) -> Analytics | D31: =IF(OR('Raw Data'!D6=0,'Raw Data'!D6="Delete"),"",'Raw Data'!D6) -> Search and Analytics - Search | E31: =IF(OR('Raw Data'!E6=0,'Raw Data'!E6="Delete"),"",'Raw Data'!E6) -> Relevance Ranking (AND, Modification date, attribute vs. FTS, specific attribute priority) | F31: {=_xlfn.SWITCH(ROUND(VLOOKUP(A31,Table1[#All],3),0),11,H31,12,I31,13,J31,14,K31,"N/A")} -> 13 | G31: {=_xlfn.SWITCH(ROUND(VLOOKUP(A31,Table1[#All],5),0),11,H31,12,I31,13,J31,14,K31,"N/A")} -> 14 | H31: =IF(OR('Raw Data'!H6=0,'Raw Data'!H6="Delete"),"",'Raw Data'!H6) -> 13 | I31: =IF(OR('Raw Data'!I6=0,'Raw Data'!I6="Delete"),"",'Raw Data'!I6) -> 14 | J31: =IF(OR('Raw Data'!J6=0,'Raw Data'!J6="Delete"),"",'Raw Data'!J6) | K31: =IF(OR('Raw Data'!K6=0,'Raw Data'!K6="Delete"),"",'Raw Data'!K6) | L31: =R31 -> Available | M31: =IF(A31="","",IF(OR(AWReleaseNum>=A31,AWReleaseNum=0),"Available","Not Supported")) -> Available | N31: =IF(A31="","",IF(TcRelease="Any","Available",IF(OR(AND(TcReleaseNum>=VLOOKUP(AWReleaseNum,MinVerInfo,3,FALSE),TcReleaseNum<=VLOOKUP(AWReleaseNum,MinVerInfo,4,FALSE)),AND(TcReleaseNum>=VLOOKUP(AWReleaseNum,MinVerInfo,5,FALSE),TcReleaseNum<=VLOOKUP(AWReleaseNum,MinVerInfo,6,FALSE))),"Available","Not Supported"))) -> Available | O31: =IF(TcReleaseNum<P31,"Not Supported","Available") -> Available | P31: {=_xlfn.SWITCH(TcBaseVer, 14, K31, 13, J31, 12, I31, 11, IFERROR(VLOOKUP(H31,Table2[#All],3,FALSE),"N/A"),0)} -> 0 | Q31: =IF(TcBaseVer=0,M31,IF(AND(N31="Available",M31="Available",O31="Available"),"Available",IF(M31="","","Not Supported"))) -> Available | R31: =IF(A31>=AWCurrentRel, "Future",Q31) -> Available | S31: =HYPERLINK(U31,T31) -> Not Available | T31: =IFERROR(VLOOKUP(CONCATENATE($B31,"_",$A31),Table4[#All],5,FALSE),"Not Available") -> Not Available | U31: =IFERROR(VLOOKUP(CONCATENATE(B31,"_",A31),Table4[#All],6,FALSE),"")
A32: =IF(OR('Raw Data'!A7=0,'Raw Data'!A7="Delete"),"",'Raw Data'!A7) -> 2 | B32: =IF(OR('Raw Data'!B7=0,'Raw Data'!B7="Delete"),"",'Raw Data'!B7) -> Deliver | C32: =IF(OR('Raw Data'!C7=0,'Raw Data'!C7="Delete"),"",'Raw Data'!C7) -> Analytics | D32: =IF(OR('Raw Data'!D7=0,'Raw Data'!D7="Delete"),"",'Raw Data'!D7) -> Search and Analytics - Search | E32: =IF(OR('Raw Data'!E7=0,'Raw Data'!E7="Delete"),"",'Raw Data'!E7) -> Accurate results based on access rules | F32: {=_xlfn.SWITCH(ROUND(VLOOKUP(A32,Table1[#All],3),0),11,H32,12,I32,13,J32,14,K32,"N/A")} -> 13 | G32: {=_xlfn.SWITCH(ROUND(VLOOKUP(A32,Table1[#All],5),0),11,H32,12,I32,13,J32,14,K32,"N/A")} -> 14 | H32: =IF(OR('Raw Data'!H7=0,'Raw Data'!H7="Delete"),"",'Raw Data'!H7) -> 13 | I32: =IF(OR('Raw Data'!I7=0,'Raw Data'!I7="Delete"),"",'Raw Data'!I7) -> 14 | J32: =IF(OR('Raw Data'!J7=0,'Raw Data'!J7="Delete"),"",'Raw Data'!J7) | K32: =IF(OR('Raw Data'!K7=0,'Raw Data'!K7="Delete"),"",'Raw Data'!K7) | L32: =R32 -> Available | M32: =IF(A32="","",IF(OR(AWReleaseNum>=A32,AWReleaseNum=0),"Available","Not Supported")) -> Available | N32: =IF(A32="","",IF(TcRelease="Any","Available",IF(OR(AND(TcReleaseNum>=VLOOKUP(AWReleaseNum,MinVerInfo,3,FALSE),TcReleaseNum<=VLOOKUP(AWReleaseNum,MinVerInfo,4,FALSE)),AND(TcReleaseNum>=VLOOKUP(AWReleaseNum,MinVerInfo,5,FALSE),TcReleaseNum<=VLOOKUP(AWReleaseNum,MinVerInfo,6,FALSE))),"Available","Not Supported"))) -> Available | O32: =IF(TcReleaseNum<P32,"Not Supported","Available") -> Available | P32: {=_xlfn.SWITCH(TcBaseVer, 14, K32, 13, J32, 12, I32, 11, IFERROR(VLOOKUP(H32,Table2[#All],3,FALSE),"N/A"),0)} -> 0 | Q32: =IF(TcBaseVer=0,M32,IF(AND(N32="Available",M32="Available",O32="Available"),"Available",IF(M32="","","Not Supported"))) -> Available | R32: =IF(A32>=AWCurrentRel, "Future",Q32) -> Available | S32: =HYPERLINK(U32,T32) -> Not Available | T32: =IFERROR(VLOOKUP(CONCATENATE($B32,"_",$A32),Table4[#All],5,FALSE),"Not Available") -> Not Available | U32: =IFERROR(VLOOKUP(CONCATENATE(B32,"_",A32),Table4[#All],6,FALSE),"")
A33: =IF(OR('Raw Data'!A8=0,'Raw Data'!A8="Delete"),"",'Raw Data'!A8) -> 2 | B33: =IF(OR('Raw Data'!B8=0,'Raw Data'!B8="Delete"),"",'Raw Data'!B8) -> Deliver | C33: =IF(OR('Raw Data'!C8=0,'Raw Data'!C8="Delete"),"",'Raw Data'!C8) -> Analytics | D33: =IF(OR('Raw Data'!D8=0,'Raw Data'!D8="Delete"),"",'Raw Data'!D8) -> Search and Analytics - Search | E33: =IF(OR('Raw Data'!E8=0,'Raw Data'!E8="Delete"),"",'Raw Data'!E8) -> Aggregate Search - Preproduction support for searching from additional repositories | F33: {=_xlfn.SWITCH(ROUND(VLOOKUP(A33,Table1[#All],3),0),11,H33,12,I33,13,J33,14,K33,"N/A")} -> 13 | G33: {=_xlfn.SWITCH(ROUND(VLOOKUP(A33,Table1[#All],5),0),11,H33,12,I33,13,J33,14,K33,"N/A")} -> 14 | H33: =IF(OR('Raw Data'!H8=0,'Raw Data'!H8="Delete"),"",'Raw Data'!H8) -> 13 | I33: =IF(OR('Raw Data'!I8=0,'Raw Data'!I8="Delete"),"",'Raw Data'!I8) -> 14 | J33: =IF(OR('Raw Data'!J8=0,'Raw Data'!J8="Delete"),"",'Raw Data'!J8) | K33: =IF(OR('Raw Data'!K8=0,'Raw Data'!K8="Delete"),"",'Raw Data'!K8) | L33: =R33 -> Available | M33: =IF(A33="","",IF(OR(AWReleaseNum>=A33,AWReleaseNum=0),"Available","Not Supported")) -> Available | N33: =IF(A33="","",IF(TcRelease="Any","Available",IF(OR(AND(TcReleaseNum>=VLOOKUP(AWReleaseNum,MinVerInfo,3,FALSE),TcReleaseNum<=VLOOKUP(AWReleaseNum,MinVerInfo,4,FALSE)),AND(TcReleaseNum>=VLOOKUP(AWReleaseNum,MinVerInfo,5,FALSE),TcReleaseNum<=VLOOKUP(AWReleaseNum,MinVerInfo,6,FALSE))),"Available","Not Supported"))) -> Available | O33: =IF(TcReleaseNum<P33,"Not Supported","Available") -> Available | P33: {=_xlfn.SWITCH(TcBaseVer, 14, K33, 13, J33, 12, I33, 11, IFERROR(VLOOKUP(H33,Table2[#All],3,FALSE),"N/A"),0)} -> 0 | Q33: =IF(TcBaseVer=0,M33,IF(AND(N33="Available",M33="Available",O33="Available"),"Available",IF(M33="","","Not Supported"))) -> Available | R33: =IF(A33>=AWCurrentRel, "Future",Q33) -> Available | S33: =HYPERLINK(U33,T33) -> Not Available | T33: =IFERROR(VLOOKUP(CONCATENATE($B33,"_",$A33),Table4[#All],5,FALSE),"Not Available") -> Not Available | U33: =IFERROR(VLOOKUP(CONCATENATE(B33,"_",A33),Table4[#All],6,FALSE),"")
A34: =IF(OR('Raw Data'!A9=0,'Raw Data'!A9="Delete"),"",'Raw Data'!A9) -> 2 | B34: =IF(OR('Raw Data'!B9=0,'Raw Data'!B9="Delete"),"",'Raw Data'!B9) -> Deliver | C34: =IF(OR('Raw Data'!C9=0,'Raw Data'!C9="Delete"),"",'Raw Data'!C9) -> Analytics | D34: =IF(OR('Raw Data'!D9=0,'Raw Data'!D9="Delete"),"",'Raw Data'!D9) -> Search and Analytics - Search | E34: =IF(OR('Raw Data'!E9=0,'Raw Data'!E9="Delete"),"",'Raw Data'!E9) -> Searching on file contents as well as Business Objects Metadata | F34: {=_xlfn.SWITCH(ROUND(VLOOKUP(A34,Table1[#All],3),0),11,H34,12,I34,13,J34,14,K34,"N/A")} -> 13 | G34: {=_xlfn.SWITCH(ROUND(VLOOKUP(A34,Table1[#All],5),0),11,H34,12,I34,13,J34,14,K34,"N/A")} -> 14 | H34: =IF(OR('Raw Data'!H9=0,'Raw Data'!H9="Delete"),"",'Raw Data'!H9) -> 13 | I34: =IF(OR('Raw Data'!I9=0,'Raw Data'!I9="Delete"),"",'Raw Data'!I9) -> 14 | J34: =IF(OR('Raw Data'!J9=0,'Raw Data'!J9="Delete"),"",'Raw Data'!J9) | K34: =IF(OR('Raw Data'!K9=0,'Raw Data'!K9="Delete"),"",'Raw Data'!K9) | L34: =R34 -> Available | M34: =IF(A34="","",IF(OR(AWReleaseNum>=A34,AWReleaseNum=0),"Available","Not Supported")) -> Available | N34: =IF(A34="","",IF(TcRelease="Any","Available",IF(OR(AND(TcReleaseNum>=VLOOKUP(AWReleaseNum,MinVerInfo,3,FALSE),TcReleaseNum<=VLOOKUP(AWReleaseNum,MinVerInfo,4,FALSE)),AND(TcReleaseNum>=VLOOKUP(AWReleaseNum,MinVerInfo,5,FALSE),TcReleaseNum<=VLOOKUP(AWReleaseNum,MinVerInfo,6,FALSE))),"Available","Not Supported"))) -> Available | O34: =IF(TcReleaseNum<P34,"Not Supported","Available") -> Available | P34: {=_xlfn.SWITCH(TcBaseVer, 14, K34, 13, J34, 12, I34, 11, IFERROR(VLOOKUP(H34,Table2[#All],3,FALSE),"N/A"),0)} -> 0 | Q34: =IF(TcBaseVer=0,M34,IF(AND(N34="Available",M34="Available",O34="Available"),"Available",IF(M34="","","Not Supported"))) -> Available | R34: =IF(A34>=AWCurrentRel, "Future",Q34) -> Available | S34: =HYPERLINK(U34,T34) -> Not Available | T34: =IFERROR(VLOOKUP(CONCATENATE($B34,"_",$A34),Table4[#All],5,FALSE),"Not Available") -> Not Available | U34: =IFERROR(VLOOKUP(CONCATENATE(B34,"_",A34),Table4[#All],6,FALSE),"")
A35: =IF(OR('Raw Data'!A18=0,'Raw Data'!A18="Delete"),"",'Raw Data'!A18) -> 2 | B35: =IF(OR('Raw Data'!B18=0,'Raw Data'!B18="Delete"),"",'Raw Data'!B18) -> Deliver | C35: =IF(OR('Raw Data'!C18=0,'Raw Data'!C18="Delete"),"",'Raw Data'!C18) -> Analytics | D35: =IF(OR('Raw Data'!D18=0,'Raw Data'!D18="Delete"),"",'Raw Data'!D18) -> Search and Analytics - Search | E35: =IF(OR('Raw Data'!E18=0,'Raw Data'!E18="Delete"),"",'Raw Data'!E18) -> Searching for files (not just Business Objects) | F35: {=_xlfn.SWITCH(ROUND(VLOOKUP(A35,Table1[#All],3),0),11,H35,12,I35,13,J35,14,K35,"N/A")} -> 13 | G35: {=_xlfn.SWITCH(ROUND(VLOOKUP(A35,Table1[#All],5),0),11,H35,12,I35,13,J35,14,K35,"N/A")} -> 14 | H35: =IF(OR('Raw Data'!H18=0,'Raw Data'!H18="Delete"),"",'Raw Data'!H18) -> 13 | I35: =IF(OR('Raw Data'!I18=0,'Raw Data'!I18="Delete"),"",'Raw Data'!I18) -> 14 | J35: =IF(OR('Raw Data'!J18=0,'Raw Data'!J18="Delete"),"",'Raw Data'!J18) | K35: =IF(OR('Raw Data'!K18=0,'Raw Data'!K18="Delete"),"",'Raw Data'!K18) | L35: =R35 -> Available | M35: =IF(A35="","",IF(OR(AWReleaseNum>=A35,AWReleaseNum=0),"Available","Not Supported")) -> Available | N35: =IF(A35="","",IF(TcRelease="Any","Available",IF(OR(AND(TcReleaseNum>=VLOOKUP(AWReleaseNum,MinVerInfo,3,FALSE),TcReleaseNum<=VLOOKUP(AWReleaseNum,MinVerInfo,4,FALSE)),AND(TcReleaseNum>=VLOOKUP(AWReleaseNum,MinVerInfo,5,FALSE),TcReleaseNum<=VLOOKUP(AWReleaseNum,MinVerInfo,6,FALSE))),"Available","Not Supported"))) -> Available | O35: =IF(TcReleaseNum<P35,"Not Supported","Available") -> Available | P35: {=_xlfn.SWITCH(TcBaseVer, 14, K35, 13, J35, 12, I35, 11, IFERROR(VLOOKUP(H35,Table2[#All],3,FALSE),"N/A"),0)} -> 0 | Q35: =IF(TcBaseVer=0,M35,IF(AND(N35="Available",M35="Available",O35="Available"),"Available",IF(M35="","","Not Supported"))) -> Available | R35: =IF(A35>=AWCurrentRel, "Future",Q35) -> Available | S35: =HYPERLINK(U35,T35) -> Not Available | T35: =IFERROR(VLOOKUP(CONCATENATE($B35,"_",$A35),Table4[#All],5,FALSE),"Not Available") -> Not Available | U35: =IFERROR(VLOOKUP(CONCATENATE(B35,"_",A35),Table4[#All],6,FALSE),"")
A36: =IF(OR('Raw Data'!A19=0,'Raw Data'!A19="Delete"),"",'Raw Data'!A19) -> 2 | B36: =IF(OR('Raw Data'!B19=0,'Raw Data'!B19="Delete"),"",'Raw Data'!B19) -> Deliver | C36: =IF(OR('Raw Data'!C19=0,'Raw Data'!C19="Delete"),"",'Raw Data'!C19) -> Analytics | D36: =IF(OR('Raw Data'!D19=0,'Raw Data'!D19="Delete"),"",'Raw Data'!D19) -> Search and Analytics - Search | E36: =IF(OR('Raw Data'!E19=0,'Raw Data'!E19="Delete"),"",'Raw Data'!E19) -> Shape Search | F36: {=_xlfn.SWITCH(ROUND(VLOOKUP(A36,Table1[#All],3),0),11,H36,12,I36,13,J36,14,K36,"N/A")} -> 13 | G36: {=_xlfn.SWITCH(ROUND(VLOOKUP(A36,Table1[#All],5),0),11,H36,12,I36,13,J36,14,K36,"N/A")} -> 14 | H36: =IF(OR('Raw Data'!H19=0,'Raw Data'!H19="Delete"),"",'Raw Data'!H19) -> 13 | I36: =IF(OR('Raw Data'!I19=0,'Raw Data'!I19="Delete"),"",'Raw Data'!I19) -> 14 | J36: =IF(OR('Raw Data'!J19=0,'Raw Data'!J19="Delete"),"",'Raw Data'!J19) | K36: =IF(OR('Raw Data'!K19=0,'Raw Data'!K19="Delete"),"",'Raw Data'!K19) | L36: =R36 -> Available | M36: =IF(A36="","",IF(OR(AWReleaseNum>=A36,AWReleaseNum=0),"Available","Not Supported")) -> Available | N36: =IF(A36="","",IF(TcRelease="Any","Available",IF(OR(AND(TcReleaseNum>=VLOOKUP(AWReleaseNum,MinVerInfo,3,FALSE),TcReleaseNum<=VLOOKUP(AWReleaseNum,MinVerInfo,4,FALSE)),AND(TcReleaseNum>=VLOOKUP(AWReleaseNum,MinVerInfo,5,FALSE),TcReleaseNum<=VLOOKUP(AWReleaseNum,MinVerInfo,6,FALSE))),"Available","Not Supported"))) -> Available | O36: =IF(TcReleaseNum<P36,"Not Supported","Available") -> Available | P36: {=_xlfn.SWITCH(TcBaseVer, 14, K36, 13, J36, 12, I36, 11, IFERROR(VLOOKUP(H36,Table2[#All],3,FALSE),"N/A"),0)} -> 0 | Q36: =IF(TcBaseVer=0,M36,IF(AND(N36="Available",M36="Available",O36="Available"),"Available",IF(M36="","","Not Supported"))) -> Available | R36: =IF(A36>=AWCurrentRel, "Future",Q36) -> Available | S36: =HYPERLINK(U36,T36) -> Not Available | T36: =IFERROR(VLOOKUP(CONCATENATE($B36,"_",$A36),Table4[#All],5,FALSE),"Not Available") -> Not Available | U36: =IFERROR(VLOOKUP(CONCATENATE(B36,"_",A36),Table4[#All],6,FALSE),"")
A37: =IF(OR('Raw Data'!A20=0,'Raw Data'!A20="Delete"),"",'Raw Data'!A20) -> 2 | B37: =IF(OR('Raw Data'!B20=0,'Raw Data'!B20="Delete"),"",'Raw Data'!B20) -> Deliver | C37: =IF(OR('Raw Data'!C20=0,'Raw Data'!C20="Delete"),"",'Raw Data'!C20) -> Analytics | D37: =IF(OR('Raw Data'!D20=0,'Raw Data'!D20="Delete"),"",'Raw Data'!D20) -> Search and Analytics - Search | E37: =IF(OR('Raw Data'!E20=0,'Raw Data'!E20="Delete"),"",'Raw Data'!E20) -> Classification Search | F37: {=_xlfn.SWITCH(ROUND(VLOOKUP(A37,Table1[#All],3),0),11,H37,12,I37,13,J37,14,K37,"N/A")} -> 13 | G37: {=_xlfn.SWITCH(ROUND(VLOOKUP(A37,Table1[#All],5),0),11,H37,12,I37,13,J37,14,K37,"N/A")} -> 14 | H37: =IF(OR('Raw Data'!H20=0,'Raw Data'!H20="Delete"),"",'Raw Data'!H20) -> 13 | I37: =IF(OR('Raw Data'!I20=0,'Raw Data'!I20="Delete"),"",'Raw Data'!I20) -> 14 | J37: =IF(OR('Raw Data'!J20=0,'Raw Data'!J20="Delete"),"",'Raw Data'!J20) | K37: =IF(OR('Raw Data'!K20=0,'Raw Data'!K20="Delete"),"",'Raw Data'!K20) | L37: =R37 -> Available | M37: =IF(A37="","",IF(OR(AWReleaseNum>=A37,AWReleaseNum=0),"Available","Not Supported")) -> Available | N37: =IF(A37="","",IF(TcRelease="Any","Available",IF(OR(AND(TcReleaseNum>=VLOOKUP(AWReleaseNum,MinVerInfo,3,FALSE),TcReleaseNum<=VLOOKUP(AWReleaseNum,MinVerInfo,4,FALSE)),AND(TcReleaseNum>=VLOOKUP(AWReleaseNum,MinVerInfo,5,FALSE),TcReleaseNum<=VLOOKUP(AWReleaseNum,MinVerInfo,6,FALSE))),"Available","Not Supported"))) -> Available | O37: =IF(TcReleaseNum<P37,"Not Supported","Available") -> Available | P37: {=_xlfn.SWITCH(TcBaseVer, 14, K37, 13, J37, 12, I37, 11, IFERROR(VLOOKUP(H37,Table2[#All],3,FALSE),"N/A"),0)} -> 0 | Q37: =IF(TcBaseVer=0,M37,IF(AND(N37="Available",M37="Available",O37="Available"),"Available",IF(M37="","","Not Supported"))) -> Available | R37: =IF(A37>=AWCurrentRel, "Future",Q37) -> Available | S37: =HYPERLINK(U37,T37) -> Not Available | T37: =IFERROR(VLOOKUP(CONCATENATE($B37,"_",$A37),Table4[#All],5,FALSE),"Not Available") -> Not Available | U37: =IFERROR(VLOOKUP(CONCATENATE(B37,"_",A37),Table4[#All],6,FALSE),"")
A38: =IF(OR('Raw Data'!A21=0,'Raw Data'!A21="Delete"),"",'Raw Data'!A21) -> 2 | B38: =IF(OR('Raw Data'!B21=0,'Raw Data'!B21="Delete"),"",'Raw Data'!B21) -> Deliver | C38: =IF(OR('Raw Data'!C21=0,'Raw Data'!C21="Delete"),"",'Raw Data'!C21) -> Analytics | D38: =IF(OR('Raw Data'!D21=0,'Raw Data'!D21="Delete"),"",'Raw Data'!D21) -> Search and Analytics - Search | E38: =IF(OR('Raw Data'!E21=0,'Raw Data'!E21="Delete"),"",'Raw Data'!E21) -> One text box search | F38: {=_xlfn.SWITCH(ROUND(VLOOKUP(A38,Table1[#All],3),0),11,H38,12,I38,13,J38,14,K38,"N/A")} -> 13 | G38: {=_xlfn.SWITCH(ROUND(VLOOKUP(A38,Table1[#All],5),0),11,H38,12,I38,13,J38,14,K38,"N/A")} -> 14 | H38: =IF(OR('Raw Data'!H21=0,'Raw Data'!H21="Delete"),"",'Raw Data'!H21) -> 13 | I38: =IF(OR('Raw Data'!I21=0,'Raw Data'!I21="Delete"),"",'Raw Data'!I21) -> 14 | J38: =IF(OR('Raw Data'!J21=0,'Raw Data'!J21="Delete"),"",'Raw Data'!J21) | K38: =IF(OR('Raw Data'!K21=0,'Raw Data'!K21="Delete"),"",'Raw Data'!K21) | L38: =R38 -> Available | M38: =IF(A38="","",IF(OR(AWReleaseNum>=A38,AWReleaseNum=0),"Available","Not Supported")) -> Available | N38: =IF(A38="","",IF(TcRelease="Any","Available",IF(OR(AND(TcReleaseNum>=VLOOKUP(AWReleaseNum,MinVerInfo,3,FALSE),TcReleaseNum<=VLOOKUP(AWReleaseNum,MinVerInfo,4,FALSE)),AND(TcReleaseNum>=VLOOKUP(AWReleaseNum,MinVerInfo,5,FALSE),TcReleaseNum<=VLOOKUP(AWReleaseNum,MinVerInfo,6,FALSE))),"Available","Not Supported"))) -> Available | O38: =IF(TcReleaseNum<P38,"Not Supported","Available") -> Available | P38: {=_xlfn.SWITCH(TcBaseVer, 14, K38, 13, J38, 12, I38, 11, IFERROR(VLOOKUP(H38,Table2[#All],3,FALSE),"N/A"),0)} -> 0 | Q38: =IF(TcBaseVer=0,M38,IF(AND(N38="Available",M38="Available",O38="Available"),"Available",IF(M38="","","Not Supported"))) -> Available | R38: =IF(A38>=AWCurrentRel, "Future",Q38) -> Available | S38: =HYPERLINK(U38,T38) -> Not Available | T38: =IFERROR(VLOOKUP(CONCATENATE($B38,"_",$A38),Table4[#All],5,FALSE),"Not Available") -> Not Available | U38: =IFERROR(VLOOKUP(CONCATENATE(B38,"_",A38),Table4[#All],6,FALSE),"")
A39: =IF(OR('Raw Data'!A22=0,'Raw Data'!A22="Delete"),"",'Raw Data'!A22) -> 2 | B39: =IF(OR('Raw Data'!B22=0,'Raw Data'!B22="Delete"),"",'Raw Data'!B22) -> Deliver | C39: =IF(OR('Raw Data'!C22=0,'Raw Data'!C22="Delete"),"",'Raw Data'!C22) -> Analytics | D39: =IF(OR('Raw Data'!D22=0,'Raw Data'!D22="Delete"),"",'Raw Data'!D22) -> Search and Analytics - Search | E39: =IF(OR('Raw Data'!E22=0,'Raw Data'!E22="Delete"),"",'Raw Data'!E22) -> Filter results via bar chart | F39: {=_xlfn.SWITCH(ROUND(VLOOKUP(A39,Table1[#All],3),0),11,H39,12,I39,13,J39,14,K39,"N/A")} -> 13 | G39: {=_xlfn.SWITCH(ROUND(VLOOKUP(A39,Table1[#All],5),0),11,H39,12,I39,13,J39,14,K39,"N/A")} -> 14 | H39: =IF(OR('Raw Data'!H22=0,'Raw Data'!H22="Delete"),"",'Raw Data'!H22) -> 13 | I39: =IF(OR('Raw Data'!I22=0,'Raw Data'!I22="Delete"),"",'Raw Data'!I22) -> 14 | J39: =IF(OR('Raw Data'!J22=0,'Raw Data'!J22="Delete"),"",'Raw Data'!J22) | K39: =IF(OR('Raw Data'!K22=0,'Raw Data'!K22="Delete"),"",'Raw Data'!K22) | L39: =R39 -> Available | M39: =IF(A39="","",IF(OR(AWReleaseNum>=A39,AWReleaseNum=0),"Available","Not Supported")) -> Available | N39: =IF(A39="","",IF(TcRelease="Any","Available",IF(OR(AND(TcReleaseNum>=VLOOKUP(AWReleaseNum,MinVerInfo,3,FALSE),TcReleaseNum<=VLOOKUP(AWReleaseNum,MinVerInfo,4,FALSE)),AND(TcReleaseNum>=VLOOKUP(AWReleaseNum,MinVerInfo,5,FALSE),TcReleaseNum<=VLOOKUP(AWReleaseNum,MinVerInfo,6,FALSE))),"Available","Not Supported"))) -> Available | O39: =IF(TcReleaseNum<P39,"Not Supported","Available") -> Available | P39: {=_xlfn.SWITCH(TcBaseVer, 14, K39, 13, J39, 12, I39, 11, IFERROR(VLOOKUP(H39,Table2[#All],3,FALSE),"N/A"),0)} -> 0 | Q39: =IF(TcBaseVer=0,M39,IF(AND(N39="Available",M39="Available",O39="Available"),"Available",IF(M39="","","Not Supported"))) -> Available | R39: =IF(A39>=AWCurrentRel, "Future",Q39) -> Available | S39: =HYPERLINK(U39,T39) -> Not Available | T39: =IFERROR(VLOOKUP(CONCATENATE($B39,"_",$A39),Table4[#All],5,FALSE),"Not Available") -> Not Available | U39: =IFERROR(VLOOKUP(CONCATENATE(B39,"_",A39),Table4[#All],6,FALSE),"")
A40: =IF(OR('Raw Data'!A23=0,'Raw Data'!A23="Delete"),"",'Raw Data'!A23) -> 2 | B40: =IF(OR('Raw Data'!B23=0,'Raw Data'!B23="Delete"),"",'Raw Data'!B23) -> Deliver | C40: =IF(OR('Raw Data'!C23=0,'Raw Data'!C23="Delete"),"",'Raw Data'!C23) -> Analytics | D40: =IF(OR('Raw Data'!D23=0,'Raw Data'!D23="Delete"),"",'Raw Data'!D23) -> Search and Analytics - Search | E40: =IF(OR('Raw Data'!E23=0,'Raw Data'!E23="Delete"),"",'Raw Data'!E23) -> Filter results via fly out filter panel | F40: {=_xlfn.SWITCH(ROUND(VLOOKUP(A40,Table1[#All],3),0),11,H40,12,I40,13,J40,14,K40,"N/A")} -> 13 | G40: {=_xlfn.SWITCH(ROUND(VLOOKUP(A40,Table1[#All],5),0),11,H40,12,I40,13,J40,14,K40,"N/A")} -> 14 | H40: =IF(OR('Raw Data'!H23=0,'Raw Data'!H23="Delete"),"",'Raw Data'!H23) -> 13 | I40: =IF(OR('Raw Data'!I23=0,'Raw Data'!I23="Delete"),"",'Raw Data'!I23) -> 14 | J40: =IF(OR('Raw Data'!J23=0,'Raw Data'!J23="Delete"),"",'Raw Data'!J23) | K40: =IF(OR('Raw Data'!K23=0,'Raw Data'!K23="Delete"),"",'Raw Data'!K23) | L40: =R40 -> Available | M40: =IF(A40="","",IF(OR(AWReleaseNum>=A40,AWReleaseNum=0),"Available","Not Supported")) -> Available | N40: =IF(A40="","",IF(TcRelease="Any","Available",IF(OR(AND(TcReleaseNum>=VLOOKUP(AWReleaseNum,MinVerInfo,3,FALSE),TcReleaseNum<=VLOOKUP(AWReleaseNum,MinVerInfo,4,FALSE)),AND(TcReleaseNum>=VLOOKUP(AWReleaseNum,MinVerInfo,5,FALSE),TcReleaseNum<=VLOOKUP(AWReleaseNum,MinVerInfo,6,FALSE))),"Available","Not Supported"))) -> Available | O40: =IF(TcReleaseNum<P40,"Not Supported","Available") -> Available | P40: {=_xlfn.SWITCH(TcBaseVer, 14, K40, 13, J40, 12, I40, 11, IFERROR(VLOOKUP(H40,Table2[#All],3,FALSE),"N/A"),0)} -> 0 | Q40: =IF(TcBaseVer=0,M40,IF(AND(N40="Available",M40="Available",O40="Available"),"Available",IF(M40="","","Not Supported"))) -> Available | R40: =IF(A40>=AWCurrentRel, "Future",Q40) -> Available | S40: =HYPERLINK(U40,T40) -> Not Available | T40: =IFERROR(VLOOKUP(CONCATENATE($B40,"_",$A40),Table4[#All],5,FALSE),"Not Available") -> Not Available | U40: =IFERROR(VLOOKUP(CONCATENATE(B40,"_",A40),Table4[#All],6,FALSE),"")
A41: =IF(OR('Raw Data'!A24=0,'Raw Data'!A24="Delete"),"",'Raw Data'!A24) -> 2 | B41: =IF(OR('Raw Data'!B24=0,'Raw Data'!B24="Delete"),"",'Raw Data'!B24) -> Deliver | C41: =IF(OR('Raw Data'!C24=0,'Raw Data'!C24="Delete"),"",'Raw Data'!C24) -> Analytics | D41: =IF(OR('Raw Data'!D24=0,'Raw Data'!D24="Delete"),"",'Raw Data'!D24) -> Search and Analytics - Search | E41: =IF(OR('Raw Data'!E24=0,'Raw Data'!E24="Delete"),"",'Raw Data'!E24) -> Open Results | F41: {=_xlfn.SWITCH(ROUND(VLOOKUP(A41,Table1[#All],3),0),11,H41,12,I41,13,J41,14,K41,"N/A")} -> 13 | G41: {=_xlfn.SWITCH(ROUND(VLOOKUP(A41,Table1[#All],5),0),11,H41,12,I41,13,J41,14,K41,"N/A")} -> 14 | H41: =IF(OR('Raw Data'!H24=0,'Raw Data'!H24="Delete"),"",'Raw Data'!H24) -> 13 | I41: =IF(OR('Raw Data'!I24=0,'Raw Data'!I24="Delete"),"",'Raw Data'!I24) -> 14 | J41: =IF(OR('Raw Data'!J24=0,'Raw Data'!J24="Delete"),"",'Raw Data'!J24) | K41: =IF(OR('Raw Data'!K24=0,'Raw Data'!K24="Delete"),"",'Raw Data'!K24) | L41: =R41 -> Available | M41: =IF(A41="","",IF(OR(AWReleaseNum>=A41,AWReleaseNum=0),"Available","Not Supported")) -> Available | N41: =IF(A41="","",IF(TcRelease="Any","Available",IF(OR(AND(TcReleaseNum>=VLOOKUP(AWReleaseNum,MinVerInfo,3,FALSE),TcReleaseNum<=VLOOKUP(AWReleaseNum,MinVerInfo,4,FALSE)),AND(TcReleaseNum>=VLOOKUP(AWReleaseNum,MinVerInfo,5,FALSE),TcReleaseNum<=VLOOKUP(AWReleaseNum,MinVerInfo,6,FALSE))),"Available","Not Supported"))) -> Available | O41: =IF(TcReleaseNum<P41,"Not Supported","Available") -> Available | P41: {=_xlfn.SWITCH(TcBaseVer, 14, K41, 13, J41, 12, I41, 11, IFERROR(VLOOKUP(H41,Table2[#All],3,FALSE),"N/A"),0)} -> 0 | Q41: =IF(TcBaseVer=0,M41,IF(AND(N41="Available",M41="Available",O41="Available"),"Available",IF(M41="","","Not Supported"))) -> Available | R41: =IF(A41>=AWCurrentRel, "Future",Q41) -> Available | S41: =HYPERLINK(U41,T41) -> Not Available | T41: =IFERROR(VLOOKUP(CONCATENATE($B41,"_",$A41),Table4[#All],5,FALSE),"Not Available") -> Not Available | U41: =IFERROR(VLOOKUP(CONCATENATE(B41,"_",A41),Table4[#All],6,FALSE),"")
